using System.Collections.Immutable;

namespace Orleans.FluentResults;

public partial record Result
{

    #region Merge

    /// <summary>
    ///     Merge multiple result objects to one result object together
    /// </summary>
    public static Result Merge(params Result[] results)
    {
        ArgumentNullException.ThrowIfNull(results);
        return ResultHelper.Merge(results);
    }

    #endregion


    #region Fail If

    /// <summary>
    ///     Create a success/failed result depending on the parameter isFailure
    /// </summary>
    public static Result FailIf(bool isFailure, Error error)
    {
        return isFailure ? Fail(error) : Ok();
    }

    /// <summary>
    ///     Create a success/failed result depending on the parameter isFailure
    /// </summary>
    public static Result FailIf(bool isFailure, string errorMessage)
    {
        return isFailure ? Fail(errorMessage) : Ok();
    }

    /// <summary>
    ///     Create a success/failed result depending on the parameter isFailure
    /// </summary>
    /// <remarks>
    ///     Error is lazily evaluated.
    /// </remarks>
    public static Result FailIf(bool isFailure, Func<Error> errorFactory)
    {
        ArgumentNullException.ThrowIfNull(errorFactory);
        return isFailure ? Fail(errorFactory.Invoke()) : Ok();
    }

    /// <summary>
    ///     Create a success/failed result depending on the parameter isFailure
    /// </summary>
    /// <remarks>
    ///     Error is lazily evaluated.
    /// </remarks>
    public static Result FailIf(bool isFailure, Func<string> errorMessageFactory)
    {
        ArgumentNullException.ThrowIfNull(errorMessageFactory);
        return isFailure ? Fail(errorMessageFactory.Invoke()) : Ok();
    }

    #endregion

    #region Try

    /// <summary>
    ///     Executes the action. If an exception is thrown within the action then this exception is transformed via the catchHandler to an Error object
    /// </summary>
    public static Result Try(Action action, Func<Exception, Error>? catchHandler = null)
    {
        ArgumentNullException.ThrowIfNull(action);
        catchHandler ??= ResultSettings.Current.DefaultTryCatchHandler;
        try
        {
            action();
            return Ok();
        }
        catch (Exception ex)
        {
            return Fail(catchHandler(ex));
        }
    }

    /// <summary>
    ///     Executes the action. If an exception is thrown within the action then this exception is transformed via the catchHandler to an Error object
    /// </summary>
    public static async Task<Result> Try(Func<Task> action, Func<Exception, Error>? catchHandler = null)
    {
        ArgumentNullException.ThrowIfNull(action);
        catchHandler ??= ResultSettings.Current.DefaultTryCatchHandler;
        try
        {
            await action();
            return Ok();
        }
        catch (Exception ex)
        {
            return Fail(catchHandler(ex));
        }
    }

    /// <summary>
    ///     Executes the action. If an exception is thrown within the action then this exception is transformed via the catchHandler to an Error object
    /// </summary>
    public static async ValueTask<Result> Try(Func<ValueTask> action, Func<Exception, Error>? catchHandler = null)
    {
        ArgumentNullException.ThrowIfNull(action);
        catchHandler ??= ResultSettings.Current.DefaultTryCatchHandler;
        try
        {
            await action();
            return Ok();
        }
        catch (Exception ex)
        {
            return Fail(catchHandler(ex));
        }
    }

    #endregion

}
